<?xml version="0.0" ?>
<robot name="table.urdf">
	<link name="baseLink">
		<inertial>
			<origin rpy="0.00000 -0.00000 0.00000" xyz="0.00000 0.00000 0.00000"/>
			<mass value="0.00000"/>
			<inertia ixx="0.00000" ixy="0" ixz="0" iyy="0.00000" iyz="0" izz="0.00000"/>
		</inertial>
		<visual>
			<origin rpy="0.00000 -0.00000 0.00000" xyz="0.00000 0.00000 0.60000"/>
			<geometry>
				<mesh filename="/home/robolab/software/bullet3/data/table/table.obj" scale="1.50000 1.00000 0.05000"/>
			</geometry>
			<material name="mat_-1_0">
				<color rgba="1.00000 1.00000 1.00000 1.00000" />
			</material>
		</visual>
		<visual>
			<origin rpy="0.00000 -0.00000 0.00000" xyz="-0.65000 -0.40000 0.29000"/>
			<geometry>
				<mesh filename="/home/robolab/software/bullet3/data/table/table.obj" scale="0.10000 0.10000 0.58000"/>
			</geometry>
			<material name="mat_-1_1">
				<color rgba="1.00000 1.00000 1.00000 1.00000" />
			</material>
		</visual>
		<visual>
			<origin rpy="0.00000 -0.00000 0.00000" xyz="-0.65000 0.40000 0.29000"/>
			<geometry>
				<mesh filename="/home/robolab/software/bullet3/data/table/table.obj" scale="0.10000 0.10000 0.58000"/>
			</geometry>
			<material name="mat_-1_2">
				<color rgba="1.00000 1.00000 1.00000 1.00000" />
			</material>
		</visual>
		<visual>
			<origin rpy="0.00000 -0.00000 0.00000" xyz="0.65000 -0.40000 0.29000"/>
			<geometry>
				<mesh filename="/home/robolab/software/bullet3/data/table/table.obj" scale="0.10000 0.10000 0.58000"/>
			</geometry>
			<material name="mat_-1_3">
				<color rgba="1.00000 1.00000 1.00000 1.00000" />
			</material>
		</visual>
		<visual>
			<origin rpy="0.00000 -0.00000 0.00000" xyz="0.65000 0.40000 0.29000"/>
			<geometry>
				<mesh filename="/home/robolab/software/bullet3/data/table/table.obj" scale="0.10000 0.10000 0.58000"/>
			</geometry>
			<material name="mat_-1_4">
				<color rgba="1.00000 1.00000 1.00000 1.00000" />
			</material>
		</visual>
		<collision>
			<origin rpy="0.00000 -0.00000 0.00000" xyz="0.00000 0.00000 0.60000"/>
			<geometry>
				<box size="1.50000 1.00000 0.05000"/>
			</geometry>
		</collision>
	</link>
	<link name="base_link">
		<inertial>
			<origin rpy="0.00000 -0.00000 0.00000" xyz="-0.00065 -0.00017 0.08449"/>
			<mass value="1.69700"/>
			<inertia ixx="0.00579" ixy="0" ixz="0" iyy="0.00579" iyz="0" izz="0.00273"/>
		</inertial>
		<visual>
			<origin rpy="0.00000 -0.00000 0.00000" xyz="0.00000 0.00000 0.00000"/>
			<geometry>
				<mesh filename="/home/robolab/robocomp_ws/src/robocomp/components/manipulation_kinova_gen3/pybullet_controller/kinova/kinova_with_pybullet/meshes/base_link.STL" scale="1.00000 1.00000 1.00000"/>
			</geometry>
			<material name="mat_-1_0">
				<color rgba="0.75294 0.75294 0.75294 1.00000" />
			</material>
		</visual>
		<collision>
			<origin rpy="0.00000 -0.00000 0.00000" xyz="0.00000 0.00000 0.00000"/>
			<geometry>
				<mesh filename="/home/robolab/robocomp_ws/src/robocomp/components/manipulation_kinova_gen3/pybullet_controller/kinova/kinova_with_pybullet/meshes/base_link.STL" scale="1.00000 1.00000 1.00000"/>
			</geometry>
		</collision>
	</link>
	<link name="shoulder_link">
		<inertial>
			<origin rpy="0.00000 -0.00000 0.00000" xyz="-0.00002 -0.01036 -0.07336"/>
			<mass value="1.37730"/>
			<inertia ixx="0.00480" ixy="0" ixz="0" iyy="0.00476" iyz="0" izz="0.00228"/>
		</inertial>
		<visual>
			<origin rpy="0.00000 -0.00000 0.00000" xyz="0.00000 0.00000 0.00000"/>
			<geometry>
				<mesh filename="/home/robolab/robocomp_ws/src/robocomp/components/manipulation_kinova_gen3/pybullet_controller/kinova/kinova_with_pybullet/meshes/shoulder_link.STL" scale="1.00000 1.00000 1.00000"/>
			</geometry>
			<material name="mat_0_0">
				<color rgba="0.75294 0.75294 0.75294 1.00000" />
			</material>
		</visual>
		<collision>
			<origin rpy="0.00000 -0.00000 0.00000" xyz="0.00000 0.00000 0.00000"/>
			<geometry>
				<mesh filename="/home/robolab/robocomp_ws/src/robocomp/components/manipulation_kinova_gen3/pybullet_controller/kinova/kinova_with_pybullet/meshes/shoulder_link.STL" scale="1.00000 1.00000 1.00000"/>
			</geometry>
		</collision>
	</link>
	<link name="half_arm_1_link">
		<inertial>
			<origin rpy="0.00000 -0.00000 0.00000" xyz="-0.00004 -0.09958 -0.01328"/>
			<mass value="1.16360"/>
			<inertia ixx="0.00842" ixy="0" ixz="0" iyy="0.00192" iyz="0" izz="0.00836"/>
		</inertial>
		<visual>
			<origin rpy="0.00000 -0.00000 0.00000" xyz="0.00000 0.00000 0.00000"/>
			<geometry>
				<mesh filename="/home/robolab/robocomp_ws/src/robocomp/components/manipulation_kinova_gen3/pybullet_controller/kinova/kinova_with_pybullet/meshes/half_arm_1_link.STL" scale="1.00000 1.00000 1.00000"/>
			</geometry>
			<material name="mat_1_0">
				<color rgba="0.75294 0.75294 0.75294 1.00000" />
			</material>
		</visual>
		<collision>
			<origin rpy="0.00000 -0.00000 0.00000" xyz="0.00000 0.00000 0.00000"/>
			<geometry>
				<mesh filename="/home/robolab/robocomp_ws/src/robocomp/components/manipulation_kinova_gen3/pybullet_controller/kinova/kinova_with_pybullet/meshes/half_arm_1_link.STL" scale="1.00000 1.00000 1.00000"/>
			</geometry>
		</collision>
	</link>
	<link name="half_arm_2_link">
		<inertial>
			<origin rpy="0.00000 -0.00000 0.00000" xyz="-0.00004 -0.00664 -0.11789"/>
			<mass value="1.16360"/>
			<inertia ixx="0.00754" ixy="0" ixz="0" iyy="0.00749" iyz="0" izz="0.00192"/>
		</inertial>
		<visual>
			<origin rpy="0.00000 -0.00000 0.00000" xyz="0.00000 0.00000 0.00000"/>
			<geometry>
				<mesh filename="/home/robolab/robocomp_ws/src/robocomp/components/manipulation_kinova_gen3/pybullet_controller/kinova/kinova_with_pybullet/meshes/half_arm_2_link.STL" scale="1.00000 1.00000 1.00000"/>
			</geometry>
			<material name="mat_2_0">
				<color rgba="0.75294 0.75294 0.75294 1.00000" />
			</material>
		</visual>
		<collision>
			<origin rpy="0.00000 -0.00000 0.00000" xyz="0.00000 0.00000 0.00000"/>
			<geometry>
				<mesh filename="/home/robolab/robocomp_ws/src/robocomp/components/manipulation_kinova_gen3/pybullet_controller/kinova/kinova_with_pybullet/meshes/half_arm_2_link.STL" scale="1.00000 1.00000 1.00000"/>
			</geometry>
		</collision>
	</link>
	<link name="forearm_link">
		<inertial>
			<origin rpy="0.00000 -0.00000 0.00000" xyz="-0.00002 -0.07548 -0.01501"/>
			<mass value="0.93020"/>
			<inertia ixx="0.00641" ixy="0" ixz="0" iyy="0.00138" iyz="0" izz="0.00652"/>
		</inertial>
		<visual>
			<origin rpy="0.00000 -0.00000 0.00000" xyz="0.00000 0.00000 0.00000"/>
			<geometry>
				<mesh filename="/home/robolab/robocomp_ws/src/robocomp/components/manipulation_kinova_gen3/pybullet_controller/kinova/kinova_with_pybullet/meshes/forearm_link.STL" scale="1.00000 1.00000 1.00000"/>
			</geometry>
			<material name="mat_3_0">
				<color rgba="0.75294 0.75294 0.75294 1.00000" />
			</material>
		</visual>
		<collision>
			<origin rpy="0.00000 -0.00000 0.00000" xyz="0.00000 0.00000 0.00000"/>
			<geometry>
				<mesh filename="/home/robolab/robocomp_ws/src/robocomp/components/manipulation_kinova_gen3/pybullet_controller/kinova/kinova_with_pybullet/meshes/forearm_link.STL" scale="1.00000 1.00000 1.00000"/>
			</geometry>
		</collision>
	</link>
	<link name="spherical_wrist_1_link">
		<inertial>
			<origin rpy="0.00000 -0.00000 0.00000" xyz="0.00000 -0.00943 -0.06388"/>
			<mass value="0.67810"/>
			<inertia ixx="0.00168" ixy="0" ixz="0" iyy="0.00151" iyz="0" izz="0.00083"/>
		</inertial>
		<visual>
			<origin rpy="0.00000 -0.00000 0.00000" xyz="0.00000 0.00000 0.00000"/>
			<geometry>
				<mesh filename="/home/robolab/robocomp_ws/src/robocomp/components/manipulation_kinova_gen3/pybullet_controller/kinova/kinova_with_pybullet/meshes/spherical_wrist_1_link.STL" scale="1.00000 1.00000 1.00000"/>
			</geometry>
			<material name="mat_4_0">
				<color rgba="0.75294 0.75294 0.75294 1.00000" />
			</material>
		</visual>
		<collision>
			<origin rpy="0.00000 -0.00000 0.00000" xyz="0.00000 0.00000 0.00000"/>
			<geometry>
				<mesh filename="/home/robolab/robocomp_ws/src/robocomp/components/manipulation_kinova_gen3/pybullet_controller/kinova/kinova_with_pybullet/meshes/spherical_wrist_1_link.STL" scale="1.00000 1.00000 1.00000"/>
			</geometry>
		</collision>
	</link>
	<link name="spherical_wrist_2_link">
		<inertial>
			<origin rpy="0.00000 -0.00000 0.00000" xyz="0.00000 -0.04548 -0.00965"/>
			<mass value="0.67810"/>
			<inertia ixx="0.00194" ixy="0" ixz="0" iyy="0.00083" iyz="0" izz="0.00176"/>
		</inertial>
		<visual>
			<origin rpy="0.00000 -0.00000 0.00000" xyz="0.00000 0.00000 0.00000"/>
			<geometry>
				<mesh filename="/home/robolab/robocomp_ws/src/robocomp/components/manipulation_kinova_gen3/pybullet_controller/kinova/kinova_with_pybullet/meshes/spherical_wrist_2_link.STL" scale="1.00000 1.00000 1.00000"/>
			</geometry>
			<material name="mat_5_0">
				<color rgba="0.75294 0.75294 0.75294 1.00000" />
			</material>
		</visual>
		<collision>
			<origin rpy="0.00000 -0.00000 0.00000" xyz="0.00000 0.00000 0.00000"/>
			<geometry>
				<mesh filename="/home/robolab/robocomp_ws/src/robocomp/components/manipulation_kinova_gen3/pybullet_controller/kinova/kinova_with_pybullet/meshes/spherical_wrist_2_link.STL" scale="1.00000 1.00000 1.00000"/>
			</geometry>
		</collision>
	</link>
	<link name="bracelet_link">
		<inertial>
			<origin rpy="0.00000 -0.00000 0.00000" xyz="0.00028 0.01140 -0.02980"/>
			<mass value="0.50000"/>
			<inertia ixx="0.00077" ixy="0" ixz="0" iyy="0.00058" iyz="0" izz="0.00097"/>
		</inertial>
		<visual>
			<origin rpy="0.00000 -0.00000 0.00000" xyz="0.00000 0.00000 0.00000"/>
			<geometry>
				<mesh filename="/home/robolab/robocomp_ws/src/robocomp/components/manipulation_kinova_gen3/pybullet_controller/kinova/kinova_with_pybullet/meshes/bracelet_with_vision_link.STL" scale="1.00000 1.00000 1.00000"/>
			</geometry>
			<material name="mat_6_0">
				<color rgba="0.75294 0.75294 0.75294 1.00000" />
			</material>
		</visual>
		<collision>
			<origin rpy="0.00000 -0.00000 0.00000" xyz="0.00000 0.00000 0.00000"/>
			<geometry>
				<mesh filename="/home/robolab/robocomp_ws/src/robocomp/components/manipulation_kinova_gen3/pybullet_controller/kinova/kinova_with_pybullet/meshes/bracelet_with_vision_link.STL" scale="1.00000 1.00000 1.00000"/>
			</geometry>
		</collision>
	</link>
	<link name="end_effector_link">
		<inertial>
			<origin rpy="0.00000 -0.00000 0.00000" xyz="0.00000 0.00000 0.00000"/>
			<mass value="1.00000"/>
			<inertia ixx="0.00000" ixy="0" ixz="0" iyy="0.00000" iyz="0" izz="0.00000"/>
		</inertial>
	</link>
	<link name="camera_link">
		<inertial>
			<origin rpy="0.00000 -0.00000 0.00000" xyz="0.00000 0.00000 0.00000"/>
			<mass value="1.00000"/>
			<inertia ixx="0.00000" ixy="0" ixz="0" iyy="0.00000" iyz="0" izz="0.00000"/>
		</inertial>
	</link>
	<link name="camera_depth_frame">
		<inertial>
			<origin rpy="0.00000 -0.00000 0.00000" xyz="0.00000 0.00000 0.00000"/>
			<mass value="1.00000"/>
			<inertia ixx="0.00000" ixy="0" ixz="0" iyy="0.00000" iyz="0" izz="0.00000"/>
		</inertial>
	</link>
	<link name="camera_color_frame">
		<inertial>
			<origin rpy="0.00000 -0.00000 0.00000" xyz="0.00000 0.00000 0.00000"/>
			<mass value="1.00000"/>
			<inertia ixx="0.00000" ixy="0" ixz="0" iyy="0.00000" iyz="0" izz="0.00000"/>
		</inertial>
	</link>
	<link name="tool_frame">
		<inertial>
			<origin rpy="0.00000 -0.00000 0.00000" xyz="0.00000 0.00000 0.00000"/>
			<mass value="1.00000"/>
			<inertia ixx="0.00000" ixy="0" ixz="0" iyy="0.00000" iyz="0" izz="0.00000"/>
		</inertial>
	</link>
	<link name="robotiq_arg2f_base_link">
		<inertial>
			<origin rpy="0.00000 -0.00000 0.00000" xyz="0.00000 -0.00000 0.03145"/>
			<mass value="0.22652"/>
			<inertia ixx="0.00034" ixy="0" ixz="0" iyy="0.00031" iyz="0" izz="0.00028"/>
		</inertial>
		<visual>
			<origin rpy="0.00000 -0.00000 0.00000" xyz="0.00000 0.00000 0.00000"/>
			<geometry>
				<mesh filename="/home/robolab/robocomp_ws/src/robocomp/components/manipulation_kinova_gen3/pybullet_controller/kinova/kinova_with_pybullet/meshes/collision/robotiq_arg2f_base_link_85.stl" scale="1.00000 1.00000 1.00000"/>
			</geometry>
			<material name="mat_12_0">
				<color rgba="0.10000 0.10000 0.10000 1.00000" />
			</material>
		</visual>
		<collision>
			<origin rpy="0.00000 -0.00000 0.00000" xyz="0.00000 0.00000 0.00000"/>
			<geometry>
				<mesh filename="/home/robolab/robocomp_ws/src/robocomp/components/manipulation_kinova_gen3/pybullet_controller/kinova/kinova_with_pybullet/meshes/collision/robotiq_arg2f_base_link_85.stl" scale="1.00000 1.00000 1.00000"/>
			</geometry>
		</collision>
	</link>
	<link name="left_outer_knuckle">
		<inertial>
			<origin rpy="0.00000 -0.00000 0.00000" xyz="-0.00020 0.01994 0.02922"/>
			<mass value="0.00853"/>
			<inertia ixx="0.00000" ixy="0" ixz="0" iyy="0.00000" iyz="0" izz="0.00000"/>
		</inertial>
		<visual>
			<origin rpy="0.00000 -0.00000 0.00000" xyz="0.00000 0.00000 0.00000"/>
			<geometry>
				<mesh filename="/home/robolab/robocomp_ws/src/robocomp/components/manipulation_kinova_gen3/pybullet_controller/kinova/kinova_with_pybullet/meshes/visual/robotiq_arg2f_85_outer_knuckle.dae" scale="0.00100 0.00100 0.00100"/>
			</geometry>
			<material name="mat_13_0">
				<color rgba="0.90000 0.90000 0.90000 1.00000" />
			</material>
		</visual>
		<collision>
			<origin rpy="0.00000 -0.00000 0.00000" xyz="0.00000 0.00000 0.00000"/>
			<geometry>
				<mesh filename="/home/robolab/robocomp_ws/src/robocomp/components/manipulation_kinova_gen3/pybullet_controller/kinova/kinova_with_pybullet/meshes/collision/robotiq_arg2f_85_outer_knuckle.dae" scale="0.00100 0.00100 0.00100"/>
			</geometry>
		</collision>
	</link>
	<link name="left_outer_finger">
		<inertial>
			<origin rpy="0.00000 -0.00000 0.00000" xyz="0.00030 0.03739 -0.02080"/>
			<mass value="0.02261"/>
			<inertia ixx="0.00001" ixy="0" ixz="0" iyy="0.00001" iyz="0" izz="0.00000"/>
		</inertial>
		<visual>
			<origin rpy="0.00000 -0.00000 0.00000" xyz="0.00000 0.00000 0.00000"/>
			<geometry>
				<mesh filename="/home/robolab/robocomp_ws/src/robocomp/components/manipulation_kinova_gen3/pybullet_controller/kinova/kinova_with_pybullet/meshes/visual/robotiq_arg2f_85_outer_finger.dae" scale="0.00100 0.00100 0.00100"/>
			</geometry>
			<material name="mat_14_0">
				<color rgba="0.10000 0.10000 0.10000 1.00000" />
			</material>
		</visual>
		<collision>
			<origin rpy="0.00000 -0.00000 0.00000" xyz="0.00000 0.00000 0.00000"/>
			<geometry>
				<mesh filename="/home/robolab/robocomp_ws/src/robocomp/components/manipulation_kinova_gen3/pybullet_controller/kinova/kinova_with_pybullet/meshes/collision/robotiq_arg2f_85_outer_finger.dae" scale="0.00100 0.00100 0.00100"/>
			</geometry>
		</collision>
	</link>
	<link name="left_inner_finger">
		<inertial>
			<origin rpy="0.00000 -0.00000 0.00000" xyz="0.00030 0.01601 -0.01369"/>
			<mass value="0.01040"/>
			<inertia ixx="0.00000" ixy="0" ixz="0" iyy="0.00000" iyz="0" izz="0.00000"/>
		</inertial>
		<visual>
			<origin rpy="0.00000 -0.00000 0.00000" xyz="0.00000 0.00000 0.00000"/>
			<geometry>
				<mesh filename="/home/robolab/robocomp_ws/src/robocomp/components/manipulation_kinova_gen3/pybullet_controller/kinova/kinova_with_pybullet/meshes/visual/robotiq_arg2f_85_inner_finger.dae" scale="0.00100 0.00100 0.00100"/>
			</geometry>
			<material name="mat_15_0">
				<color rgba="0.10000 0.10000 0.10000 1.00000" />
			</material>
		</visual>
		<collision>
			<origin rpy="0.00000 -0.00000 0.00000" xyz="0.00000 0.00000 0.00000"/>
			<geometry>
				<mesh filename="/home/robolab/robocomp_ws/src/robocomp/components/manipulation_kinova_gen3/pybullet_controller/kinova/kinova_with_pybullet/meshes/collision/robotiq_arg2f_85_inner_finger.dae" scale="0.00100 0.00100 0.00100"/>
			</geometry>
		</collision>
	</link>
	<link name="left_inner_finger_pad">
		<inertial>
			<origin rpy="0.00000 -0.00000 0.00000" xyz="0.00000 0.00000 0.00000"/>
			<mass value="1.00000"/>
			<inertia ixx="0.00012" ixy="0" ixz="0" iyy="0.00016" iyz="0" izz="0.00004"/>
		</inertial>
		<visual>
			<origin rpy="0.00000 -0.00000 0.00000" xyz="0.00000 0.00000 0.00000"/>
			<geometry>
				<box size="0.02200 0.00635 0.03750"/>
			</geometry>
			<material name="mat_16_0">
				<color rgba="0.90000 0.90000 0.90000 1.00000" />
			</material>
		</visual>
		<collision>
			<origin rpy="0.00000 -0.00000 0.00000" xyz="0.00000 0.00000 0.00000"/>
			<geometry>
				<box size="0.02200 0.00635 0.03750"/>
			</geometry>
		</collision>
	</link>
	<link name="left_inner_knuckle">
		<inertial>
			<origin rpy="0.00000 -0.00000 0.00000" xyz="0.00012 0.05079 0.00104"/>
			<mass value="0.02712"/>
			<inertia ixx="0.00002" ixy="0" ixz="0" iyy="0.00001" iyz="0" izz="0.00001"/>
		</inertial>
		<visual>
			<origin rpy="0.00000 -0.00000 0.00000" xyz="0.00000 0.00000 0.00000"/>
			<geometry>
				<mesh filename="/home/robolab/robocomp_ws/src/robocomp/components/manipulation_kinova_gen3/pybullet_controller/kinova/kinova_with_pybullet/meshes/visual/robotiq_arg2f_85_inner_knuckle.dae" scale="0.00100 0.00100 0.00100"/>
			</geometry>
			<material name="mat_17_0">
				<color rgba="0.10000 0.10000 0.10000 1.00000" />
			</material>
		</visual>
		<collision>
			<origin rpy="0.00000 -0.00000 0.00000" xyz="0.00000 0.00000 0.00000"/>
			<geometry>
				<mesh filename="/home/robolab/robocomp_ws/src/robocomp/components/manipulation_kinova_gen3/pybullet_controller/kinova/kinova_with_pybullet/meshes/collision/robotiq_arg2f_85_inner_knuckle.dae" scale="0.00100 0.00100 0.00100"/>
			</geometry>
		</collision>
	</link>
	<link name="right_outer_knuckle">
		<inertial>
			<origin rpy="0.00000 -0.00000 0.00000" xyz="-0.00020 0.01994 0.02922"/>
			<mass value="0.00853"/>
			<inertia ixx="0.00000" ixy="0" ixz="0" iyy="0.00000" iyz="0" izz="0.00000"/>
		</inertial>
		<visual>
			<origin rpy="0.00000 -0.00000 0.00000" xyz="0.00000 0.00000 0.00000"/>
			<geometry>
				<mesh filename="/home/robolab/robocomp_ws/src/robocomp/components/manipulation_kinova_gen3/pybullet_controller/kinova/kinova_with_pybullet/meshes/visual/robotiq_arg2f_85_outer_knuckle.dae" scale="0.00100 0.00100 0.00100"/>
			</geometry>
			<material name="mat_18_0">
				<color rgba="0.90000 0.90000 0.90000 1.00000" />
			</material>
		</visual>
		<collision>
			<origin rpy="0.00000 -0.00000 0.00000" xyz="0.00000 0.00000 0.00000"/>
			<geometry>
				<mesh filename="/home/robolab/robocomp_ws/src/robocomp/components/manipulation_kinova_gen3/pybullet_controller/kinova/kinova_with_pybullet/meshes/collision/robotiq_arg2f_85_outer_knuckle.dae" scale="0.00100 0.00100 0.00100"/>
			</geometry>
		</collision>
	</link>
	<link name="right_outer_finger">
		<inertial>
			<origin rpy="0.00000 -0.00000 0.00000" xyz="0.00030 0.03739 -0.02080"/>
			<mass value="0.02261"/>
			<inertia ixx="0.00001" ixy="0" ixz="0" iyy="0.00001" iyz="0" izz="0.00000"/>
		</inertial>
		<visual>
			<origin rpy="0.00000 -0.00000 0.00000" xyz="0.00000 0.00000 0.00000"/>
			<geometry>
				<mesh filename="/home/robolab/robocomp_ws/src/robocomp/components/manipulation_kinova_gen3/pybullet_controller/kinova/kinova_with_pybullet/meshes/visual/robotiq_arg2f_85_outer_finger.dae" scale="0.00100 0.00100 0.00100"/>
			</geometry>
			<material name="mat_19_0">
				<color rgba="0.10000 0.10000 0.10000 1.00000" />
			</material>
		</visual>
		<collision>
			<origin rpy="0.00000 -0.00000 0.00000" xyz="0.00000 0.00000 0.00000"/>
			<geometry>
				<mesh filename="/home/robolab/robocomp_ws/src/robocomp/components/manipulation_kinova_gen3/pybullet_controller/kinova/kinova_with_pybullet/meshes/collision/robotiq_arg2f_85_outer_finger.dae" scale="0.00100 0.00100 0.00100"/>
			</geometry>
		</collision>
	</link>
	<link name="right_inner_finger">
		<inertial>
			<origin rpy="0.00000 -0.00000 0.00000" xyz="0.00030 0.01601 -0.01369"/>
			<mass value="0.01040"/>
			<inertia ixx="0.00000" ixy="0" ixz="0" iyy="0.00000" iyz="0" izz="0.00000"/>
		</inertial>
		<visual>
			<origin rpy="0.00000 -0.00000 0.00000" xyz="0.00000 0.00000 0.00000"/>
			<geometry>
				<mesh filename="/home/robolab/robocomp_ws/src/robocomp/components/manipulation_kinova_gen3/pybullet_controller/kinova/kinova_with_pybullet/meshes/visual/robotiq_arg2f_85_inner_finger.dae" scale="0.00100 0.00100 0.00100"/>
			</geometry>
			<material name="mat_20_0">
				<color rgba="0.10000 0.10000 0.10000 1.00000" />
			</material>
		</visual>
		<collision>
			<origin rpy="0.00000 -0.00000 0.00000" xyz="0.00000 0.00000 0.00000"/>
			<geometry>
				<mesh filename="/home/robolab/robocomp_ws/src/robocomp/components/manipulation_kinova_gen3/pybullet_controller/kinova/kinova_with_pybullet/meshes/collision/robotiq_arg2f_85_inner_finger.dae" scale="0.00100 0.00100 0.00100"/>
			</geometry>
		</collision>
	</link>
	<link name="right_inner_finger_pad">
		<inertial>
			<origin rpy="0.00000 -0.00000 0.00000" xyz="0.00000 0.00000 0.00000"/>
			<mass value="1.00000"/>
			<inertia ixx="0.00012" ixy="0" ixz="0" iyy="0.00016" iyz="0" izz="0.00004"/>
		</inertial>
		<visual>
			<origin rpy="0.00000 -0.00000 0.00000" xyz="0.00000 0.00000 0.00000"/>
			<geometry>
				<box size="0.02200 0.00635 0.03750"/>
			</geometry>
			<material name="mat_21_0">
				<color rgba="0.90000 0.90000 0.90000 1.00000" />
			</material>
		</visual>
		<collision>
			<origin rpy="0.00000 -0.00000 0.00000" xyz="0.00000 0.00000 0.00000"/>
			<geometry>
				<box size="0.02200 0.00635 0.03750"/>
			</geometry>
		</collision>
	</link>
	<link name="right_inner_knuckle">
		<inertial>
			<origin rpy="0.00000 -0.00000 0.00000" xyz="0.00012 0.05079 0.00104"/>
			<mass value="0.02712"/>
			<inertia ixx="0.00002" ixy="0" ixz="0" iyy="0.00001" iyz="0" izz="0.00001"/>
		</inertial>
		<visual>
			<origin rpy="0.00000 -0.00000 0.00000" xyz="0.00000 0.00000 0.00000"/>
			<geometry>
				<mesh filename="/home/robolab/robocomp_ws/src/robocomp/components/manipulation_kinova_gen3/pybullet_controller/kinova/kinova_with_pybullet/meshes/visual/robotiq_arg2f_85_inner_knuckle.dae" scale="0.00100 0.00100 0.00100"/>
			</geometry>
			<material name="mat_22_0">
				<color rgba="0.10000 0.10000 0.10000 1.00000" />
			</material>
		</visual>
		<collision>
			<origin rpy="0.00000 -0.00000 0.00000" xyz="0.00000 0.00000 0.00000"/>
			<geometry>
				<mesh filename="/home/robolab/robocomp_ws/src/robocomp/components/manipulation_kinova_gen3/pybullet_controller/kinova/kinova_with_pybullet//meshes/collision/robotiq_arg2f_85_inner_knuckle.dae" scale="0.00100 0.00100 0.00100"/>
			</geometry>
		</collision>
	</link>
	<joint name="joint_dummy1" type="fixed">
		<parent link="baseLink"/>
		<child link="base_link"/>
		<dynamics damping="1.0" friction="0.0001"/>
		<origin rpy="0.00000 0.00000 0.00000" xyz="0.00000 0.00000 0.00000"/>
		<axis xyz="0.00000 0.00000 1.00000"/>
	</joint>
	<joint name="joint_1" type="continuous">
		<parent link="base_link"/>
		<child link="shoulder_link"/>
		<dynamics damping="1.0" friction="0.0001"/>
		<origin rpy="-3.14159 0.00000 0.00000" xyz="0.00000 0.00000 0.15643"/>
		<axis xyz="0.00000 0.00000 1.00000"/>
	</joint>
	<joint name="joint_2" type="revolute">
		<parent link="shoulder_link"/>
		<child link="half_arm_1_link"/>
		<limit effort="39.00000" lower="-2.24000" upper="2.24000" velocity="1.39630"/>
		<dynamics damping="1.0" friction="0.0001"/>
		<origin rpy="1.57080 0.00000 -0.00000" xyz="0.00000 0.00537 -0.12838"/>
		<axis xyz="0.00000 0.00000 1.00000"/>
	</joint>
	<joint name="joint_3" type="continuous">
		<parent link="half_arm_1_link"/>
		<child link="half_arm_2_link"/>
		<dynamics damping="1.0" friction="0.0001"/>
		<origin rpy="-1.57080 0.00000 -0.00000" xyz="0.00000 -0.21038 -0.00637"/>
		<axis xyz="0.00000 0.00000 1.00000"/>
	</joint>
	<joint name="joint_4" type="revolute">
		<parent link="half_arm_2_link"/>
		<child link="forearm_link"/>
		<limit effort="39.00000" lower="-2.57000" upper="2.57000" velocity="1.39630"/>
		<dynamics damping="1.0" friction="0.0001"/>
		<origin rpy="1.57080 -0.00000 -0.00000" xyz="0.00000 0.00638 -0.21038"/>
		<axis xyz="0.00000 0.00000 1.00000"/>
	</joint>
	<joint name="joint_5" type="continuous">
		<parent link="forearm_link"/>
		<child link="spherical_wrist_1_link"/>
		<dynamics damping="1.0" friction="0.0001"/>
		<origin rpy="-1.57080 0.00000 -0.00000" xyz="0.00000 -0.20843 -0.00637"/>
		<axis xyz="0.00000 0.00000 1.00000"/>
	</joint>
	<joint name="joint_6" type="revolute">
		<parent link="spherical_wrist_1_link"/>
		<child link="spherical_wrist_2_link"/>
		<limit effort="9.00000" lower="-2.09000" upper="2.09000" velocity="1.22180"/>
		<dynamics damping="1.0" friction="0.0001"/>
		<origin rpy="1.57080 -0.00000 -0.00000" xyz="0.00000 0.00018 -0.10593"/>
		<axis xyz="0.00000 0.00000 1.00000"/>
	</joint>
	<joint name="joint_7" type="continuous">
		<parent link="spherical_wrist_2_link"/>
		<child link="bracelet_link"/>
		<dynamics damping="1.0" friction="0.0001"/>
		<origin rpy="-1.57080 -0.00000 0.00000" xyz="0.00000 -0.10593 -0.00018"/>
		<axis xyz="0.00000 0.00000 1.00000"/>
	</joint>
	<joint name="end_effector" type="fixed">
		<parent link="bracelet_link"/>
		<child link="end_effector_link"/>
		<dynamics damping="1.0" friction="0.0001"/>
		<origin rpy="3.14159 0.00000 -0.00000" xyz="0.00000 0.00000 -0.06153"/>
		<axis xyz="0.00000 0.00000 0.00000"/>
	</joint>
	<joint name="camera_module" type="fixed">
		<parent link="end_effector_link"/>
		<child link="camera_link"/>
		<dynamics damping="1.0" friction="0.0001"/>
		<origin rpy="-0.00000 0.00000 3.14159" xyz="0.00000 0.05639 -0.00305"/>
		<axis xyz="0.00000 0.00000 0.00000"/>
	</joint>
	<joint name="depth_module" type="fixed">
		<parent link="end_effector_link"/>
		<child link="camera_depth_frame"/>
		<dynamics damping="1.0" friction="0.0001"/>
		<origin rpy="-0.00000 0.00000 3.14159" xyz="0.02750 0.06600 -0.00305"/>
		<axis xyz="0.00000 0.00000 0.00000"/>
	</joint>
	<joint name="color_module" type="fixed">
		<parent link="end_effector_link"/>
		<child link="camera_color_frame"/>
		<dynamics damping="1.0" friction="0.0001"/>
		<origin rpy="-0.00000 0.00000 3.14159" xyz="0.00000 0.05639 -0.00305"/>
		<axis xyz="0.00000 0.00000 0.00000"/>
	</joint>
	<joint name="tool_frame_joint" type="fixed">
		<parent link="end_effector_link"/>
		<child link="tool_frame"/>
		<dynamics damping="1.0" friction="0.0001"/>
		<origin rpy="0.00000 -0.00000 0.00000" xyz="0.00000 0.00000 0.12000"/>
		<axis xyz="0.00000 0.00000 0.00000"/>
	</joint>
	<joint name="gripper_base_joint" type="fixed">
		<parent link="end_effector_link"/>
		<child link="robotiq_arg2f_base_link"/>
		<dynamics damping="1.0" friction="0.0001"/>
		<origin rpy="0.00000 -0.00000 1.57000" xyz="0.00000 0.00000 0.00000"/>
		<axis xyz="0.00000 0.00000 0.00000"/>
	</joint>
	<joint name="finger_joint" type="revolute">
		<parent link="robotiq_arg2f_base_link"/>
		<child link="left_outer_knuckle"/>
		<limit effort="1000.00000" lower="0.00000" upper="0.80000" velocity="2.00000"/>
		<dynamics damping="1.0" friction="0.0001"/>
		<origin rpy="0.00000 -0.00000 3.14159" xyz="0.00000 -0.03060 0.05490"/>
		<axis xyz="1.00000 0.00000 0.00000"/>
	</joint>
	<joint name="left_outer_finger_joint" type="fixed">
		<parent link="left_outer_knuckle"/>
		<child link="left_outer_finger"/>
		<dynamics damping="1.0" friction="0.0001"/>
		<origin rpy="0.00000 -0.00000 0.00000" xyz="0.00000 0.03150 -0.00410"/>
		<axis xyz="0.00000 0.00000 0.00000"/>
	</joint>
	<joint name="left_inner_finger_joint" type="revolute">
		<parent link="left_outer_finger"/>
		<child link="left_inner_finger"/>
		<limit effort="1000.00000" lower="-0.87570" upper="0.87570" velocity="2.00000"/>
		<dynamics damping="1.0" friction="0.0001"/>
		<origin rpy="0.00000 -0.00000 0.00000" xyz="0.00000 0.00610 0.04710"/>
		<axis xyz="1.00000 0.00000 0.00000"/>
	</joint>
	<joint name="left_inner_finger_pad_joint" type="fixed">
		<parent link="left_inner_finger"/>
		<child link="left_inner_finger_pad"/>
		<dynamics damping="1.0" friction="0.0001"/>
		<origin rpy="0.00000 -0.00000 0.00000" xyz="0.00000 -0.02202 0.03242"/>
		<axis xyz="0.00000 0.00000 0.00000"/>
	</joint>
	<joint name="left_inner_knuckle_joint" type="revolute">
		<parent link="robotiq_arg2f_base_link"/>
		<child link="left_inner_knuckle"/>
		<limit effort="1000.00000" lower="0.00000" upper="0.87570" velocity="2.00000"/>
		<dynamics damping="1.0" friction="0.0001"/>
		<origin rpy="0.00000 -0.00000 3.14159" xyz="0.00000 -0.01270 0.06142"/>
		<axis xyz="1.00000 0.00000 0.00000"/>
	</joint>
	<joint name="right_outer_knuckle_joint" type="revolute">
		<parent link="robotiq_arg2f_base_link"/>
		<child link="right_outer_knuckle"/>
		<limit effort="1000.00000" lower="0.00000" upper="0.81000" velocity="2.00000"/>
		<dynamics damping="1.0" friction="0.0001"/>
		<origin rpy="0.00000 -0.00000 0.00000" xyz="0.00000 0.03060 0.05490"/>
		<axis xyz="1.00000 0.00000 0.00000"/>
	</joint>
	<joint name="right_outer_finger_joint" type="fixed">
		<parent link="right_outer_knuckle"/>
		<child link="right_outer_finger"/>
		<dynamics damping="1.0" friction="0.0001"/>
		<origin rpy="0.00000 -0.00000 0.00000" xyz="0.00000 0.03150 -0.00410"/>
		<axis xyz="0.00000 0.00000 0.00000"/>
	</joint>
	<joint name="right_inner_finger_joint" type="revolute">
		<parent link="right_outer_finger"/>
		<child link="right_inner_finger"/>
		<limit effort="1000.00000" lower="-0.87570" upper="0.87570" velocity="2.00000"/>
		<dynamics damping="1.0" friction="0.0001"/>
		<origin rpy="0.00000 -0.00000 0.00000" xyz="0.00000 0.00610 0.04710"/>
		<axis xyz="1.00000 0.00000 0.00000"/>
	</joint>
	<joint name="right_inner_finger_pad_joint" type="fixed">
		<parent link="right_inner_finger"/>
		<child link="right_inner_finger_pad"/>
		<dynamics damping="1.0" friction="0.0001"/>
		<origin rpy="0.00000 -0.00000 0.00000" xyz="0.00000 -0.02202 0.03242"/>
		<axis xyz="0.00000 0.00000 0.00000"/>
	</joint>
	<joint name="right_inner_knuckle_joint" type="revolute">
		<parent link="robotiq_arg2f_base_link"/>
		<child link="right_inner_knuckle"/>
		<limit effort="1000.00000" lower="0.00000" upper="0.87570" velocity="2.00000"/>
		<dynamics damping="1.0" friction="0.0001"/>
		<origin rpy="0.00000 -0.00000 0.00000" xyz="0.00000 0.01270 0.06142"/>
		<axis xyz="1.00000 0.00000 0.00000"/>
	</joint>
</robot>
